<?xml version="1.0" ?>
<!-- =================================================================================== -->
<!-- |    This document was autogenerated by xacro from ./diff_drive_robot/urdf/robot.xacro | -->
<!-- |    EDITING THIS FILE BY HAND IS NOT RECOMMENDED                                 | -->
<!-- =================================================================================== -->
<robot name="diff_drive_robot">
  <!-- Specify some standard inertial calculations https://en.wikipedia.org/wiki/List_of_moments_of_inertia -->
  <!-- These make use of xacro's mathematical functionality -->
  <!-- Base footprint (reference frame) -->
  <link name="robot_2_base_footprint">
    <visual>
      <geometry>
        <sphere radius="0.01"/>
      </geometry>
    </visual>
  </link>
  <!-- Main base link -->
  <joint name="robot_2_base_joint" type="fixed">
    <parent link="robot_2_base_footprint"/>
    <child link="robot_2_base_link"/>
    <origin rpy="0 0 0" xyz="0 0 0.075"/>
  </joint>
  <link name="robot_2_base_link">
    <visual>
      <origin rpy="0 0 0" xyz="0 0 0"/>
      <geometry>
        <box size="0.3 0.3 0.15"/>
      </geometry>
      <material name="robot_2_base_material">
        <color rgba="0.40 0.23 0.72 1.0"/>
      </material>
    </visual>
    <collision>
      <origin rpy="0 0 0" xyz="0 0 0"/>
      <geometry>
        <box size="0.3 0.3 0.15"/>
      </geometry>
    </collision>
    <inertial>
      <origin rpy="0 0 0" xyz="0 0 0"/>
      <mass value="0.5"/>
      <inertia ixx="0.004687499999999999" ixy="0.0" ixz="0.0" iyy="0.004687499999999999" iyz="0.0" izz="0.0075"/>
    </inertial>
  </link>
  <!-- Left wheel -->
  <joint name="robot_2_left_wheel_joint" type="continuous">
    <origin rpy="1.5707963267948966 0 0" xyz="0 0.175 0"/>
    <child link="robot_2_left_wheel"/>
    <parent link="robot_2_base_footprint"/>
    <axis xyz="0 0 1"/>
  </joint>
  <link name="robot_2_left_wheel">
    <inertial>
      <origin rpy="0 0 0" xyz="0 0 0"/>
      <mass value="0.1"/>
      <inertia ixx="7.583333333333335e-05" ixy="0.0" ixz="0.0" iyy="7.583333333333335e-05" iyz="0.0" izz="0.00012500000000000003"/>
    </inertial>
    <collision>
      <geometry>
        <cylinder length="0.04" radius="0.05"/>
      </geometry>
    </collision>
    <visual>
      <geometry>
        <cylinder length="0.04" radius="0.05"/>
      </geometry>
      <material name="robot_2_wheel_material">
        <color rgba="0.0 0.0 0.0 1.0"/>
      </material>
    </visual>
  </link>
  <!-- Right wheel -->
  <joint name="robot_2_right_wheel_joint" type="continuous">
    <origin rpy="1.5707963267948966 0 0" xyz="0 -0.175 0"/>
    <child link="robot_2_right_wheel"/>
    <parent link="robot_2_base_footprint"/>
    <axis xyz="0 0 1"/>
  </joint>
  <link name="robot_2_right_wheel">
    <inertial>
      <origin rpy="0 0 0" xyz="0 0 0"/>
      <mass value="0.1"/>
      <inertia ixx="7.583333333333335e-05" ixy="0.0" ixz="0.0" iyy="7.583333333333335e-05" iyz="0.0" izz="0.00012500000000000003"/>
    </inertial>
    <visual>
      <geometry>
        <cylinder length="0.04" radius="0.05"/>
      </geometry>
      <material name="robot_2_wheel_material">
        <color rgba="0.0 0.0 0.0 1.0"/>
      </material>
    </visual>
    <collision>
      <geometry>
        <cylinder length="0.04" radius="0.05"/>
      </geometry>
    </collision>
  </link>
  <!-- Castor wheel -->
  <joint name="robot_2_castor_wheel_joint" type="fixed">
    <parent link="robot_2_base_link"/>
    <child link="robot_2_castor_wheel"/>
    <origin xyz="0.15 0 -0.075"/>
  </joint>
  <link name="robot_2_castor_wheel">
    <inertial>
      <origin rpy="0 0 0" xyz="0 0 0"/>
      <mass value="0.05"/>
      <inertia ixx="5.000000000000002e-05" ixy="0.0" ixz="0.0" iyy="5.000000000000002e-05" iyz="0.0" izz="5.000000000000002e-05"/>
    </inertial>
    <visual>
      <geometry>
        <sphere radius="0.05"/>
      </geometry>
      <material name="robot_2_castor_material">
        <color rgba="0.62 0.62 0.62 1.0"/>
      </material>
    </visual>
    <collision>
      <geometry>
        <sphere radius="0.05"/>
      </geometry>
    </collision>
  </link>
  <!-- Lidar Sensor -->
  <joint name="robot_2_laser_joint" type="fixed">
    <parent link="robot_2_base_link"/>
    <child link="robot_2_laser_frame"/>
    <origin rpy="0 0 0" xyz="0.15 0 0.075"/>
  </joint>
  <link name="robot_2_laser_frame">
    <visual>
      <origin xyz="0 0 0"/>
      <geometry>
        <cylinder length="0.04" radius="0.05"/>
      </geometry>
      <material name="robot_2_laser_material">
        <color rgba="0.13 0.13 0.13 1.0"/>
      </material>
    </visual>
    <collision>
      <origin xyz="0 0 0"/>
      <geometry>
        <cylinder length="0.04" radius="0.05"/>
      </geometry>
    </collision>
    <inertial>
      <origin rpy="0 0 0" xyz="0 0 0"/>
      <mass value="0.1"/>
      <inertia ixx="7.583333333333335e-05" ixy="0.0" ixz="0.0" iyy="7.583333333333335e-05" iyz="0.0" izz="0.00012500000000000003"/>
    </inertial>
  </link>
  <!-- IMU Sensor -->
  <joint name="robot_2_imu_joint" type="fixed">
    <origin rpy="0 0 0" xyz="0 0 0.075"/>
    <parent link="robot_2_base_footprint"/>
    <child link="robot_2_imu_link"/>
  </joint>
  <link name="robot_2_imu_link">
    <visual>
      <geometry>
        <box size="0.02 0.02 0.02"/>
      </geometry>
      <material name="robot_2_imu_material">
        <color rgba="1.0 0.0 0.0 1.0"/>
      </material>
    </visual>
  </link>
  <!-- Diff Drive Plugin -->
  <gazebo>
    <plugin filename="libgz-sim-diff-drive-system.so" name="gz::sim::systems::DiffDrive">
      <left_joint>robot_2_left_wheel_joint</left_joint>
      <right_joint>robot_2_right_wheel_joint</right_joint>
      <wheel_separation>0.35</wheel_separation>
      <wheel_radius>0.05</wheel_radius>
      <odom_publish_frequency>30</odom_publish_frequency>
      <topic>model/robot_2/cmd_vel</topic>
      <odom_topic>model/robot_2/odometry</odom_topic>
    </plugin>
  </gazebo>
  <!-- Odometry Publisher -->
  <gazebo>
    <plugin filename="libgz-sim-odometry-publisher-system.so" name="gz::sim::systems::OdometryPublisher">
      <odom_frame>robot_2/odom</odom_frame>
      <robot_base_frame>robot_2_base_footprint</robot_base_frame>
      <odom_publish_frequency>30</odom_publish_frequency>
      <topic>model/robot_2/odometry</topic>
    </plugin>
  </gazebo>
  <!-- Joint State Publisher -->
  <gazebo>
    <plugin filename="libgz-sim-joint-state-publisher-system.so" name="gz::sim::systems::JointStatePublisher">
      <joint_name>robot_2_left_wheel_joint</joint_name>
      <joint_name>robot_2_right_wheel_joint</joint_name>
      <topic>model/robot_2/joint_states</topic>
    </plugin>
  </gazebo>
  <!-- IMU Sensor -->
  <gazebo reference="robot_2_imu_link">
    <gravity>true</gravity>
    <sensor name="robot_2_imu_sensor" type="imu">
      <always_on>true</always_on>
      <update_rate>100</update_rate>
      <topic>model/robot_2/imu</topic>
      <imu>
        <angular_velocity>
          <noise type="gaussian">
            <mean>0.0</mean>
            <stddev>2e-4</stddev>
          </noise>
        </angular_velocity>
        <linear_acceleration>
          <noise type="gaussian">
            <mean>0.0</mean>
            <stddev>1.7e-2</stddev>
          </noise>
        </linear_acceleration>
      </imu>
    </sensor>
  </gazebo>
  <!-- Lidar Sensor -->
  <gazebo reference="robot_2_laser_frame">
    <sensor name="robot_2_lidar_sensor" type="gpu_ray">
      <pose>0 0 0 0 0 0</pose>
      <visualize>true</visualize>
      <update_rate>10</update_rate>
      <topic>model/robot_2/scan</topic>
      <ray>
        <scan>
          <horizontal>
            <samples>360</samples>
            <resolution>1.0</resolution>
            <min_angle>-3.14159</min_angle>
            <max_angle>3.14159</max_angle>
          </horizontal>
        </scan>
        <range>
          <min>0.10</min>
          <max>10.0</max>
          <resolution>0.01</resolution>
        </range>
        <noise>
          <type>gaussian</type>
          <mean>0.0</mean>
          <stddev>0.01</stddev>
        </noise>
      </ray>
      <plugin filename="libgz-sim-sensors-system.so" name="gz::sim::systems::Sensors">
        <render_engine>ogre2</render_engine>
      </plugin>
    </sensor>
  </gazebo>
  <gazebo reference="robot_2_left_wheel">
    <mu1>1.0</mu1>
    <mu2>1.0</mu2>
  </gazebo>
  <gazebo reference="robot_2_right_wheel">
    <mu1>1.0</mu1>
    <mu2>1.0</mu2>
  </gazebo>
  <gazebo reference="robot_2_castor_wheel">
    <mu1>0.000001</mu1>
    <mu2>0.000001</mu2>
  </gazebo>
</robot>
